<?xml version="1.0" encoding="utf-8"?>
<!-- =================================================================================== -->
<!-- |    This document was autogenerated by xacro from ./urdf/ur5.urdf.xacro          | -->
<!-- |    EDITING THIS FILE BY HAND IS NOT RECOMMENDED                                 | -->
<!-- =================================================================================== -->
<robot name="ur5">
  <gazebo>
    <plugin filename="libgazebo_ros_control.so" name="ros_control">
      <!--robotNamespace>/</robotNamespace-->
      <!--robotSimType>gazebo_ros_control/DefaultRobotHWSim</robotSimType-->
    </plugin>
    <!--
    <plugin name="gazebo_ros_power_monitor_controller" filename="libgazebo_ros_power_monitor.so">
      <alwaysOn>true</alwaysOn>
      <updateRate>1.0</updateRate>
      <timeout>5</timeout>
      <powerStateTopic>power_state</powerStateTopic>
      <powerStateRate>10.0</powerStateRate>
      <fullChargeCapacity>87.78</fullChargeCapacity>     
      <dischargeRate>-474</dischargeRate>
      <chargeRate>525</chargeRate>
      <dischargeVoltage>15.52</dischargeVoltage>
      <chargeVoltage>16.41</chargeVoltage>
    </plugin>
-->
  </gazebo>
  <!-- measured from model -->
  <link name="base_link">
    <visual>
      <geometry>
        <mesh filename="package://ur_description/meshes/ur5/visual/base.dae"/>
      </geometry>
      <material name="LightGrey">
        <color rgba="0.7 0.7 0.7 1.0"/>
      </material>
    </visual>
    <collision>
      <geometry>
        <mesh filename="package://ur_description/meshes/ur5/collision/base.stl"/>
      </geometry>
    </collision>
    <inertial>
      <mass value="4.0"/>
      <origin rpy="0 0 0" xyz="0.0 0.0 0.0"/>
      <inertia ixx="0.00443333156" ixy="0.0" ixz="0.0" iyy="0.00443333156" iyz="0.0" izz="0.0072"/>
    </inertial>
  </link>
  <!-- ##################################################################################### -->
  <joint name="base_suf_joint" type="fixed">
    <parent link="base_link"/>
    <child link="base_suf_link"/>
    <origin rpy="0.0 0.0 -3.14159265359" xyz="0.0 0.0 0.0"/>
  </joint>
  <link name="base_suf_link"/>
  <joint name="shoulder_pre_joint" type="fixed">
    <parent link="base_suf_link"/>
    <child link="shoulder_pre_link"/>
    <origin rpy="0 0 3.14160348585" xyz="0 0 0.0893895156178"/>
  </joint>
  <link name="shoulder_pre_link"/>
  <!-- ##################################################################################### -->
  <joint name="shoulder_pan_joint" type="revolute">
    <parent link="shoulder_pre_link"/>
    <child link="shoulder_link"/>
    <origin rpy="0 0 3.14159265359" xyz="0 0 0"/>
    <axis xyz="0 0 1"/>
    <limit effort="150.0" lower="-6.28318530718" upper="6.28318530718" velocity="3.15"/>
    <dynamics damping="0.0" friction="0.0"/>
  </joint>
  <link name="shoulder_link">
    <visual>
      <geometry>
        <mesh filename="package://ur_description/meshes/ur5/visual/shoulder.dae"/>
      </geometry>
      <material name="LightGrey">
        <color rgba="0.7 0.7 0.7 1.0"/>
      </material>
    </visual>
    <collision>
      <geometry>
        <mesh filename="package://ur_description/meshes/ur5/collision/shoulder.stl"/>
      </geometry>
    </collision>
    <inertial>
      <mass value="3.7"/>
      <origin rpy="0 0 0" xyz="0.0 0.0 0.0"/>
      <inertia ixx="0.0149723523444" ixy="0.0" ixz="0.0" iyy="0.0149723523444" iyz="0.0" izz="0.01040625"/>
    </inertial>
  </link>
  <!-- ##################################################################################### -->
  <joint name="shoulder_suf_joint" type="fixed">
    <parent link="shoulder_link"/>
    <child link="shoulder_suf_link"/>
    <origin rpy="0 0 -3.14159265359" xyz="0 0 0"/>
  </joint>
  <link name="shoulder_suf_link"/>
  <joint name="upper_arm_pre_joint" type="fixed">
    <parent link="shoulder_suf_link"/>
    <child link="upper_arm_pre_link"/>
    <origin rpy="1.57034854095 0 2.71904566699e-05" xyz="6.33636237145e-05 0 0"/>
  </joint>
  <link name="upper_arm_pre_link"/>
  <!-- ##################################################################################### -->
  <joint name="shoulder_lift_joint" type="revolute">
    <parent link="upper_arm_pre_link"/>
    <child link="upper_arm_link"/>
    <origin rpy="1.57079632679 0 -1.57079632679" xyz="0 0 0.136"/>
    <axis xyz="0 1 0"/>
    <limit effort="150.0" lower="-6.28318530718" upper="6.28318530718" velocity="3.15"/>
    <dynamics damping="0.0" friction="0.0"/>
  </joint>
  <link name="upper_arm_link">
    <visual>
      <geometry>
        <mesh filename="package://ur_description/meshes/ur5/visual/upperarm.dae"/>
      </geometry>
      <material name="LightGrey">
        <color rgba="0.7 0.7 0.7 1.0"/>
      </material>
    </visual>
    <collision>
      <geometry>
        <mesh filename="package://ur_description/meshes/ur5/collision/upperarm.stl"/>
      </geometry>
    </collision>
    <inertial>
      <mass value="8.393"/>
      <origin rpy="0 1.57079632679 0" xyz="-0.212694808722 0.0 0.136"/>
      <inertia ixx="0.134117517137" ixy="0.0" ixz="0.0" iyy="0.134117517137" iyz="0.0" izz="0.0151074"/>
    </inertial>
  </link>
  <!-- ##################################################################################### -->
  <joint name="upper_arm_suf_joint" type="fixed">
    <parent link="upper_arm_link"/>
    <child link="upper_arm_suf_link"/>
    <origin rpy="-1.57079632679 1.57079632679 0" xyz="0 -0.136 0"/>
  </joint>
  <link name="upper_arm_suf_link"/>
  <joint name="forearm_pre_joint" type="fixed">
    <parent link="upper_arm_suf_link"/>
    <child link="forearm_pre_link"/>
    <origin rpy="3.14037678529 3.1396825367 -3.14150448323" xyz="-0.425389617445 0 0"/>
  </joint>
  <link name="forearm_pre_link"/>
  <!-- ##################################################################################### -->
  <joint name="elbow_joint" type="revolute">
    <parent link="forearm_pre_link"/>
    <child link="forearm_link"/>
    <origin rpy="1.57079632679 0 -1.57079632679" xyz="0 0 0.0165"/>
    <axis xyz="0 1 0"/>
    <limit effort="150.0" lower="-3.14159265359" upper="3.14159265359" velocity="3.15"/>
    <dynamics damping="0.0" friction="0.0"/>
  </joint>
  <link name="forearm_link">
    <visual>
      <geometry>
        <mesh filename="package://ur_description/meshes/ur5/visual/forearm.dae"/>
      </geometry>
      <material name="LightGrey">
        <color rgba="0.7 0.7 0.7 1.0"/>
      </material>
    </visual>
    <collision>
      <geometry>
        <mesh filename="package://ur_description/meshes/ur5/collision/forearm.stl"/>
      </geometry>
    </collision>
    <inertial>
      <mass value="2.275"/>
      <origin rpy="0 1.57079632679 0" xyz="-0.212694808722 0.0 0.0165"/>
      <inertia ixx="0.0312550128785" ixy="0.0" ixz="0.0" iyy="0.0312550128785" iyz="0.0" izz="0.004095"/>
    </inertial>
  </link>
  <!-- ##################################################################################### -->
  <joint name="forearm_suf_joint" type="fixed">
    <parent link="forearm_link"/>
    <child link="forearm_suf_link"/>
    <origin rpy="-1.57079632679 1.57079632679 0" xyz="0 -0.0165 0"/>
  </joint>
  <link name="forearm_suf_link"/>
  <joint name="wrist_1_pre_joint" type="fixed">
    <parent link="forearm_suf_link"/>
    <child link="wrist_1_pre_link"/>
    <origin rpy="3.13876243467 -3.14043849801 -3.14155879866" xyz="-0.392506907374 0.00031185980036 0.11018899121"/>
  </joint>
  <link name="wrist_1_pre_link"/>
  <!-- ##################################################################################### -->
  <joint name="wrist_1_joint" type="revolute">
    <parent link="wrist_1_pre_link"/>
    <child link="wrist_1_link"/>
    <origin rpy="1.57079632679 0 0" xyz="0 0 -0.093"/>
    <axis xyz="0 1 0"/>
    <limit effort="28.0" lower="-6.28318530718" upper="6.28318530718" velocity="3.2"/>
    <dynamics damping="0.0" friction="0.0"/>
  </joint>
  <link name="wrist_1_link">
    <visual>
      <geometry>
        <mesh filename="package://ur_description/meshes/ur5/visual/wrist1.dae"/>
      </geometry>
      <material name="LightGrey">
        <color rgba="0.7 0.7 0.7 1.0"/>
      </material>
    </visual>
    <collision>
      <geometry>
        <mesh filename="package://ur_description/meshes/ur5/collision/wrist1.stl"/>
      </geometry>
    </collision>
    <inertial>
      <mass value="1.219"/>
      <origin rpy="0 0 0" xyz="0.0 0.0 0.0"/>
      <inertia ixx="0.0026267351267" ixy="0.0" ixz="0.0" iyy="0.0026267351267" iyz="0.0" izz="0.0034284375"/>
    </inertial>
  </link>
  <!-- ##################################################################################### -->
  <joint name="wrist_1_suf_joint" type="fixed">
    <parent link="wrist_1_link"/>
    <child link="wrist_1_suf_link"/>
    <origin rpy="-1.57079632679 0 0" xyz="0 0.093 0"/>
  </joint>
  <link name="wrist_1_suf_link"/>
  <joint name="wrist_2_pre_joint" type="fixed">
    <parent link="wrist_1_suf_link"/>
    <child link="wrist_2_pre_link"/>
    <origin rpy="1.57075058795 0 5.49664109762e-05" xyz="3.3323577063e-05 -0.0947783958619 4.33505448434e-06"/>
  </joint>
  <link name="wrist_2_pre_link"/>
  <!-- ##################################################################################### -->
  <joint name="wrist_2_joint" type="revolute">
    <parent link="wrist_2_pre_link"/>
    <child link="wrist_2_link"/>
    <origin rpy="0 0 0" xyz="0 0 -0.095"/>
    <axis xyz="0 0 1"/>
    <limit effort="28.0" lower="-6.28318530718" upper="6.28318530718" velocity="3.2"/>
    <dynamics damping="0.0" friction="0.0"/>
  </joint>
  <link name="wrist_2_link">
    <visual>
      <geometry>
        <mesh filename="package://ur_description/meshes/ur5/visual/wrist2.dae"/>
      </geometry>
      <material name="LightGrey">
        <color rgba="0.7 0.7 0.7 1.0"/>
      </material>
    </visual>
    <collision>
      <origin rpy="0 0 0" xyz="0 0 -0.095"/>
      <geometry>
        <mesh filename="package://ur_description/meshes/ur5/collision/wrist2.stl"/>
      </geometry>
    </collision>
    <inertial>
      <mass value="1.219"/>
      <origin rpy="0 0 0" xyz="0.0 0.0 0.0"/>
      <inertia ixx="0.00178828260388" ixy="0.0" ixz="0.0" iyy="0.00178828260388" iyz="0.0" izz="0.0021942"/>
    </inertial>
  </link>
  <!-- ##################################################################################### -->
  <joint name="wrist_2_suf_joint" type="fixed">
    <parent link="wrist_2_link"/>
    <child link="wrist_2_suf_link"/>
    <origin rpy="0 0 0" xyz="0 0 0.095"/>
  </joint>
  <link name="wrist_2_suf_link"/>
  <joint name="wrist_3_pre_joint" type="fixed">
    <parent link="wrist_2_suf_link"/>
    <child link="wrist_3_pre_link"/>
    <origin rpy="1.57077086316 3.14159265359 -3.14150915496" xyz="5.02447530839e-05 0.0824869782666 -2.10041838233e-06"/>
  </joint>
  <link name="wrist_3_pre_link"/>
  <!-- ##################################################################################### -->
  <joint name="wrist_3_joint" type="revolute">
    <parent link="wrist_3_pre_link"/>
    <child link="wrist_3_link"/>
    <origin rpy="1.57079632679 0 0" xyz="0 0 -0.0818"/>
    <axis xyz="0 1 0"/>
    <limit effort="28.0" lower="-6.28318530718" upper="6.28318530718" velocity="3.2"/>
    <dynamics damping="0.0" friction="0.0"/>
  </joint>
  <link name="wrist_3_link">
    <visual>
      <geometry>
        <mesh filename="package://ur_description/meshes/ur5/visual/wrist3.dae"/>
      </geometry>
      <material name="LightGrey">
        <color rgba="0.7 0.7 0.7 1.0"/>
      </material>
    </visual>
    <collision>
      <geometry>
        <mesh filename="package://ur_description/meshes/ur5/collision/wrist3.stl"/>
      </geometry>
    </collision>
    <inertial>
      <mass value="0.1879"/>
      <origin rpy="0 0 0" xyz="0.0 0.0 -0.01525"/>
      <inertia ixx="8.06247260834e-05" ixy="0.0" ixz="0.0" iyy="8.06247260834e-05" iyz="0.0" izz="0.0001321171875"/>
    </inertial>
  </link>
  <!-- ##################################################################################### -->
  <joint name="wrist_3_suf_joint" type="fixed">
    <parent link="wrist_3_link"/>
    <child link="wrist_3_suf_link"/>
    <origin rpy="-1.57079632679 0 0" xyz="0 0.0818 0"/>
  </joint>
  <link name="wrist_3_suf_link"/>
  <joint name="ee_pre_joint" type="fixed">
    <parent link="wrist_3_suf_link"/>
    <child link="ee_pre_link"/>
    <origin rpy="0.0 -1.57079632679 1.57079632679" xyz="0.0 0.0 0.0"/>
  </joint>
  <link name="ee_pre_link"/>
  <!-- ##################################################################################### -->
  <joint name="ee_fixed_joint" type="fixed">
    <parent link="ee_pre_link"/>
    <child link="ee_link"/>
    <origin rpy="0 0 0" xyz="-0.01 0 0"/>
  </joint>
  <link name="ee_link">
    <collision>
      <geometry>
        <box size="0.01 0.01 0.01"/>
      </geometry>
    </collision>
  </link>
  <transmission name="shoulder_pan_trans">
    <type>transmission_interface/SimpleTransmission</type>
    <joint name="shoulder_pan_joint">
      <hardwareInterface>hardware_interface/PositionJointInterface</hardwareInterface>
    </joint>
    <actuator name="shoulder_pan_motor">
      <mechanicalReduction>1</mechanicalReduction>
    </actuator>
  </transmission>
  <transmission name="shoulder_lift_trans">
    <type>transmission_interface/SimpleTransmission</type>
    <joint name="shoulder_lift_joint">
      <hardwareInterface>hardware_interface/PositionJointInterface</hardwareInterface>
    </joint>
    <actuator name="shoulder_lift_motor">
      <mechanicalReduction>1</mechanicalReduction>
    </actuator>
  </transmission>
  <transmission name="elbow_trans">
    <type>transmission_interface/SimpleTransmission</type>
    <joint name="elbow_joint">
      <hardwareInterface>hardware_interface/PositionJointInterface</hardwareInterface>
    </joint>
    <actuator name="elbow_motor">
      <mechanicalReduction>1</mechanicalReduction>
    </actuator>
  </transmission>
  <transmission name="wrist_1_trans">
    <type>transmission_interface/SimpleTransmission</type>
    <joint name="wrist_1_joint">
      <hardwareInterface>hardware_interface/PositionJointInterface</hardwareInterface>
    </joint>
    <actuator name="wrist_1_motor">
      <mechanicalReduction>1</mechanicalReduction>
    </actuator>
  </transmission>
  <transmission name="wrist_2_trans">
    <type>transmission_interface/SimpleTransmission</type>
    <joint name="wrist_2_joint">
      <hardwareInterface>hardware_interface/PositionJointInterface</hardwareInterface>
    </joint>
    <actuator name="wrist_2_motor">
      <mechanicalReduction>1</mechanicalReduction>
    </actuator>
  </transmission>
  <transmission name="wrist_3_trans">
    <type>transmission_interface/SimpleTransmission</type>
    <joint name="wrist_3_joint">
      <hardwareInterface>hardware_interface/PositionJointInterface</hardwareInterface>
    </joint>
    <actuator name="wrist_3_motor">
      <mechanicalReduction>1</mechanicalReduction>
    </actuator>
  </transmission>
  <gazebo reference="shoulder_link">
    <selfCollide>true</selfCollide>
  </gazebo>
  <gazebo reference="upper_arm_link">
    <selfCollide>true</selfCollide>
  </gazebo>
  <gazebo reference="forearm_link">
    <selfCollide>true</selfCollide>
  </gazebo>
  <gazebo reference="wrist_1_link">
    <selfCollide>true</selfCollide>
  </gazebo>
  <gazebo reference="wrist_3_link">
    <selfCollide>true</selfCollide>
  </gazebo>
  <gazebo reference="wrist_2_link">
    <selfCollide>true</selfCollide>
  </gazebo>
  <gazebo reference="ee_link">
    <selfCollide>true</selfCollide>
  </gazebo>
  <!-- ROS base_link to UR 'Base' Coordinates transform -->
  <link name="base"/>
  <joint name="base_link-base_fixed_joint" type="fixed">
    <!-- NOTE: this rotation is only needed as long as base_link itself is
                 not corrected wrt the real robot (ie: rotated over 180
                 degrees)
      -->
    <origin rpy="0 0 -3.14159265359" xyz="0 0 0"/>
    <parent link="base_link"/>
    <child link="base"/>
  </joint>
  <!-- Frame coincident with all-zeros TCP on UR controller -->
  <link name="tool0"/>
  <joint name="wrist_3_passive_joint" type="fixed">
    <origin rpy="0 0 0" xyz="0 0 0"/>
    <parent link="wrist_3_link"/>
    <child link="tool0"/>
  </joint>
  <link name="world"/>
  <!-- ##################################################################################### -->
  <joint name="base_pre_joint" type="fixed">
    <parent link="world"/>
    <child link="base_pre_link"/>
    <origin rpy="0.0 0.0 0.0" xyz="0.0 0.0 0.0"/>
  </joint>
  <link name="base_pre_link"/>
  <!-- ##################################################################################### -->
  <joint name="world_joint" type="fixed">
    <parent link="base_pre_link"/>
    <child link="base_link"/>
    <origin rpy="0.0 0.0 3.14159265359" xyz="0.0 0.0 0.0"/>
  </joint>
</robot>
